<?xml version="1.0"?>
<robot name="barista_robot">

    <!-- Coloring  -->
    <material name="red">
        <color rgba="1 0 0 1"/>
    </material>

    <material name="green">
        <color rgba="0 1 0 1"/>
    </material>

    <material name="blue">
        <color rgba="0 0 1 1"/>
    </material>

    <material name="gray">
        <color rgba="0.5 0.5 0.5 1"/>
    </material>

    <material name="black">
        <color rgba="0.0 0.0 0.0 1"/>
    </material>

    <!-- Base footprint -->
    <!-- <link name="base_footprint">
    </link>

    <joint name="base_link_base_footprint_joint" type="fixed">
        <origin rpy="0 0 0" xyz="0 0 -0.0352"/>
        <parent link="base_link"/>
        <child link="base_footprint"/>
    </joint> -->

    <!-- Base link -->
    <link name="base_link">
        <collision>
            <origin xyz="0 0 0.0775"/>
            <geometry>
                <cylinder length="0.155" radius="0.178" />
            </geometry>
        </collision>

        <inertial>
            <origin xyz="0 0 0"/>
            <mass value="5.0"/>
            <inertia ixx="0.1765" ixy="0" ixz="0" iyy="0.1765" iyz="0" izz="0.044"/>
        </inertial>

        <visual>
            <origin xyz="0 0 0.0775"/>
            <geometry>
                <cylinder length="0.155" radius="0.178"/>
            </geometry>
            <material name="black"/>
        </visual>
    </link>


    <!-- Left wheel -->
    <link name="left_wheel">
        <collision>
            <origin xyz="0 0 0" rpy="-1.57079632 0 0"/>
            <geometry>
                <cylinder length="0.0206" radius="0.0352"/>
            </geometry>
        </collision>

        <inertial>
            <mass value="0.5" />
            <origin xyz="0 0 0" rpy="-1.57079632 0 0" />
            <inertia ixx="0.001" ixy="0" ixz="0" iyy="0.001" iyz="0" izz="0.0005"/>
        </inertial>

        <visual>
            <origin xyz="0 0 0" rpy="-1.57079632 0 0"/>
            <geometry>
                <cylinder length="0.0206" radius="0.0352"/>
            </geometry>
            <material name="red"/>
        </visual>
    </link>

    <joint name="base_link_left_wheel_joint" type="continuous">
        <axis xyz="0 1 0" rpy="0 0 0" />
        <origin xyz="0 0.15 0.0" rpy="0 0 0" />
        <parent link="base_link" />
        <child link="left_wheel" />
    </joint>


    <!-- right wheel -->
    <link name="right_wheel">
        <collision>
            <origin xyz="0 0 0" rpy="-1.57079632 0 0"/>
            <geometry>
                <cylinder length="0.0206" radius="0.0352"/>
            </geometry>
        </collision>

        <inertial>
            <mass value="0.5" />
            <origin xyz="0 0 0" rpy="-1.57079632 0 0" />
            <inertia ixx="0.001" ixy="0" ixz="0" iyy="0.001" iyz="0" izz="0.0005"/>
        </inertial>

        <visual>
            <origin xyz="0 0 0" rpy="-1.57079632 0 0"/>
            <geometry>
                <cylinder length="0.0206" radius="0.0352"/>
            </geometry>
            <material name="red"/>
        </visual>
    </link>

    <joint name="base_link_right_wheel_joint" type="continuous">
        <axis xyz="0 1 0" rpy="0 0 0" />
        <origin xyz="0 -0.15 0.0" rpy="0 0 0" />
        <parent link="base_link" />
        <child link="right_wheel" />
    </joint>

    <!-- laser -->
    <link name="laser">
        <collision>
            <origin xyz="0 0 0" rpy="0 0 0"/>
            <geometry>
                <mesh filename="file:///home/user/ros2_ws/src/barista_robot_description/meshes/hokuyo_urg_04lx.stl" scale="1 1 1" />
            </geometry>
        </collision>

        <inertial>
            <mass value="1.0"/>
            <origin xyz="0 0 0"/>
            <inertia ixx="0.0045" ixy="0" ixz="0" iyy="0.0045" iyz="0" izz="0.00225"/>
        </inertial>

        <visual>
            <origin xyz="0 0 0"/>
            <geometry>
                <mesh filename="file:///home/user/ros2_ws/src/barista_robot_description/meshes/hokuyo_urg_04lx.stl" scale="1 1 1" />
            </geometry>
        </visual>
    </link>

    <joint name="base_link_laser_joint" type="fixed">
        <origin rpy="0 0 0" xyz="0 0 0.155" />
        <parent link="base_link" />
        <child link="laser" />
    </joint>


    <!-- right standoff -->
    <link name="right_standoff">
        <collision>
            <origin xyz="0 0 0.110" rpy="0 0 0"/>
            <geometry>
                <cylinder length="0.220" radius="0.01"/>
            </geometry>
        </collision>

        <inertial>
            <mass value="1" />
            <origin xyz="0 0 0" rpy="0 0 0" />
            <inertia ixx="0.002" ixy="0" ixz="0" iyy="0.002" iyz="0" izz="0.001"/>
        </inertial>

        <visual>
            <origin xyz="0 0 0.110" rpy="0 0 0"/>
            <geometry>
                <cylinder length="0.220" radius="0.01"/>
            </geometry>
            <material name="gray"/>
        </visual>
    </link>

    <joint name="base_link_right_standoff_joint" type="fixed">
        <origin rpy="0 0 0" xyz="0 -0.125 0.155" />
        <parent link="base_link" />
        <child link="right_standoff" />
    </joint>

    <!-- left standoff -->
    <link name="left_standoff">
        <collision>
            <origin xyz="0 0 0.110" rpy="0 0 0"/>
            <geometry>
                <cylinder length="0.220" radius="0.01"/>
            </geometry>
        </collision>

        <inertial>
            <mass value="1" />
            <origin xyz="0 0 0" rpy="0 0 0" />
            <inertia ixx="0.002" ixy="0" ixz="0" iyy="0.002" iyz="0" izz="0.001"/>
        </inertial>

        <visual>
            <origin xyz="0 0 0.110" rpy="0 0 0"/>
            <geometry>
                <cylinder length="0.220" radius="0.01"/>
            </geometry>
            <material name="gray"/>
        </visual>
    </link>

    <joint name="base_link_left_standoff_joint" type="fixed">
        <origin rpy="0 0 0" xyz="0 0.125 0.155" />
        <parent link="base_link" />
        <child link="left_standoff" />
    </joint>

    <!-- cup holder link -->
    <link name="cup_holder">
        <collision>
            <origin xyz="0 0 0" rpy="0 0 0"/>
            <geometry>
                <cylinder length="0.09" radius="0.160"/>
            </geometry>
        </collision>
        <inertial>
            <origin xyz="0 0 0"/>
            <mass value="2.0"/>
            <inertia ixx="0.0512" ixy="0" ixz="0" iyy="0.0512" iyz="0" izz="0.0256"/>
        </inertial>
        <visual>
            <origin xyz="0 0 0"/>
            <geometry>
                <cylinder length="0.09" radius="0.160"/>
            </geometry>
            <material name="blue"/>
        </visual>
    </link>

    <joint name="base_link_cup_holder_joint" type="fixed">
        <origin rpy="0 0 0" xyz="0 0 0.42" />
        <parent link="base_link" />
        <child link="cup_holder" />
    </joint>


    <!-- Front caster -->
    <link name="front_caster">
        <collision>
            <origin xyz="0 0 -0.0176" rpy="0 0 0"/>
            <geometry>
                <cylinder length="0.0352" radius="0.01" />
            </geometry>
        </collision>

        <inertial>
            <mass value="1" />
            <origin xyz="0 0 0" rpy="0 0 0" />
            <inertia ixx="0.0001274" ixy="0.0" ixz="0.0" iyy="0.0001274" iyz="0.0" izz="0.00005" />
        </inertial>

        <visual>
            <origin xyz="0 0 -0.0176" rpy="0 0 0"/>
            <geometry>
                <cylinder length="0.0352" radius="0.01" />
            </geometry>
            <material name="gray"/>
        </visual>
    </link>

    <joint name="base_link_front_caster_joint" type="fixed">
        <origin rpy="0 0 0" xyz="0.125 0 0" />
        <parent link="base_link" />
        <child link="front_caster" />
    </joint>

    <!-- Rear caster -->
    <link name="rear_caster">
        <collision>
            <origin xyz="0 0 -0.0176" rpy="0 0 0"/>
            <geometry>
                <cylinder length="0.0352" radius="0.01" />
            </geometry>
        </collision>

        <inertial>
            <mass value="1" />
            <origin xyz="0 0 0" rpy="0 0 0" />
            <inertia ixx="0.0001274" ixy="0.0" ixz="0.0" iyy="0.0001274" iyz="0.0" izz="0.00005" />
        </inertial>

        <visual>
            <origin xyz="0 0 -0.0176" rpy="0 0 0"/>
            <geometry>
                <cylinder length="0.0352" radius="0.01" />
            </geometry>
            <material name="gray"/>
        </visual>
    </link>

    <joint name="base_link_rear_caster_joint" type="fixed">
        <origin rpy="0 0 0" xyz="-0.125 0 0" />
        <parent link="base_link" />
        <child link="rear_caster" />
    </joint>



    <!-- Gazebo Properties -->
    <gazebo reference="base_link">
        <material>Gazebo/Black</material>
    </gazebo>

    <gazebo reference="cup_holder">
        <material>Gazebo/Blue</material>
    </gazebo>

    <gazebo reference="left_wheel">
        <material>Gazebo/Red</material>
        <mu1>1</mu1>
        <mu2>1</mu2>
    </gazebo>

    <gazebo reference="right_wheel">
        <material>Gazebo/Red</material>
        <mu1>1</mu1>
        <mu2>1</mu2>
    </gazebo>

    <gazebo reference="front_caster">
        <mu1>0</mu1>
        <mu2>0</mu2>
        <material>Gazebo/Gray</material>
    </gazebo>

    <gazebo reference="rear_caster">
        <mu1>0</mu1>
        <mu2>0</mu2>
        <material>Gazebo/Gray</material>
    </gazebo>

    <!-- Gazebo Plugins -->
    <!-- Robot differential driver -->
    <gazebo>
        <plugin filename="libgazebo_ros_diff_drive.so" name="differential_drive_controller">
            <update_rate>20</update_rate>

            <left_joint>base_link_left_wheel_joint</left_joint>
            <right_joint>base_link_right_wheel_joint</right_joint>

            <wheel_separation>0.3</wheel_separation>
            <wheel_diameter>0.0352</wheel_diameter>
            <!-- limits -->
            <max_wheel_torque>1.0</max_wheel_torque>
            <max_wheel_acceleration>2.0</max_wheel_acceleration>
            <!-- odom -->
            <publish_odom>true</publish_odom>
            <publish_odom_tf>true</publish_odom_tf>
            <odometry_frame>odom</odometry_frame>

            <command_topic>cmd_vel</command_topic>
            <robot_base_frame>base_link</robot_base_frame>
        </plugin>
    </gazebo>

    <!-- Laser scan -->
    <gazebo reference="base_link_laser_joint">
        <preserveFixedJoint>true</preserveFixedJoint>
    </gazebo>

    <gazebo reference="laser">
        <sensor type="ray" name="head_hokuyo_sensor">
            <pose>0 0 0 0 0 0</pose>
            <visualize>true</visualize>
            <update_rate>20</update_rate>
            <ray>
                <scan>
                    <horizontal>
                        <samples>720</samples>
                        <resolution>1</resolution>
                        <min_angle>-3.141592</min_angle>
                        <max_angle>3.141592</max_angle>
                    </horizontal>
                </scan>
                <range>
                    <min>0.2</min>
                    <max>10.0</max>
                    <resolution>0.01</resolution>
                </range>
                <noise>
                    <type>gaussian</type>
                    <mean>0.0</mean>
                    <stddev>0.01</stddev>
                </noise>
            </ray>
            <plugin name="laser" filename="libgazebo_ros_ray_sensor.so">
                <ros>
                    <remapping>/laser/out:=/scan</remapping>
                </ros>
                <output_type>sensor_msgs/LaserScan</output_type>
            </plugin>
        </sensor>
    </gazebo>

</robot>
